Workbook

Sheet 01 README
A1: BUILDING RATE ANALYSIS MASTER DATABASE – FINAL (Pakistan, city-selectable)
A2: Doc: RA_Master_Pakistan_FINAL_Rev07_2026-09-27
A4: Purpose | B4: Transparent, formula-driven rate library for BOQ, tender checking, VO pricing and cost planning. Every rate is built A-material + wastage + labour + plant + transport → direct cost → OH → profit → optional tax.
A5: Scope – this issue | B5: FINAL MERGED Rev06 (rates filled from GRN register, Punjab MRS 2026, dashboard research): every trade + depth variants + 11-city selector + 16 RFQ sheet (fill quotes once, whole library updates). Rev03 added Phases 4–9: prelims, earthwork, doors, windows, joinery, façade, external works, plumbing, fire fighting, electrical, ELV, life safety, HVAC, lifts, misc. Vendor/system items carry full component structure with red inputs for quotes. Phase 3 (Rev02) added: porcelain/ceramic floor & wall tiling, marble flooring, gypsum ceilings (full component build-up), emulsion & weather-shield paint systems. Phase 2 (Rev01) added: formwork (slab, beam, column, wall), block masonry 8"/6"/4", brick 4.5", screeds 1.5"/2"/3", waterproofing (torch-on membrane, cementitious, DPC). Phase 1: 15 lab mix-design concretes transcribed from the user's 8 lab sheets (1000–6000 PSI), 3 nominal concretes, rebar, 9" brick masonry, 2 plaster items. Trade list (12) carries the full coding for all trades; items are queued, not invented.
A6: Rate basis | B6: City selector in 10 ASSUMPTIONS (default Lahore). Lahore: Sep-2026 market indications from dated web sources (09). Conflicting sources shown as Low/High in 05; working value flagged yellow.
A7: Units | B7: cft, Sft, kg, Nos, bag, litre, day, PKR. Lab batch weights converted via Batch_cft = 35.315.
A8: Colour key | B8: Blue = input · Green = formula · Yellow = assumption / dated market indication · Red = NO dated source – blank until filled · Grey = totals.
A9: How to update | B9: 1) Enter new rates in 05/06/07 col 'Base Rate' with date & source ID. 2) Change globals in 10. 3) Check 14 QC = OK. Never type into green cells.
A10: Reprice a mix | B10: Change 'Priced as' material code or batch kg in 15; analysis in 04 follows automatically.
A11: Add an item | B11: Copy an analysis block in 04, change code/resources, add a row in 03 pointing to the new block's summary cells.
A12: Critical inputs still blank | B12: Admixture, water, binding wire, Zinda Pir sand, nails, release oil, membrane, primer, bitumen, LPG, cementitious slurry, all plant/prop hire; timber rate OLD (Feb-2025) – all rate statuses show INCOMPLETE until entered.
A13: Not included | B13: Formwork, pumping floor premium, cradle/scaffold for elevations, taxes (toggle), escalation.
A14: Rev07 (2026-09-27) | B14: Reconciled with the SAJ QSCOST dashboard Rate Analysis library: one dated rate per shared resource (cement 1,575, Lawrencepur 240, Sargodha 185, Margalla 180, A-brick 17.5, blocks 140/165, sub-base 100, plaster mason 2,150, tile fixer 2,500, painter 2,100); crew outputs checked against Punjab MRS 2026 labour shares, MAK installation rates and SRC-06 piece rates (13, columns H–S); 35 new analyses; 17 Missing Items Register; 18 Dashboard Reconciliation; 19 Revision Log.
A15: Dashboard link | B15: Every item in 03 is in the dashboard Item Library under the same code, with the same resources and adjusted quantities (Rate Analysis → Item Library, category filter). Shared resources use the dashboard Rate Database line named in 18.

Sheet 02 DASHBOARD
A1: 02 · DASHBOARD
A2: Rate basis: Lahore · Rev07 reconciled with dashboard · Last updated 2026-09-27
A4: Metric | B4: Value
A5: Total rate analyses | B5: =COUNTA('03 MASTER RATE LIBRARY'!A5:A400) -> 160
A6: Complete (no blank inputs) | B6: =COUNTIF('03 MASTER RATE LIBRARY'!W5:W400,0) -> 126
A7: Incomplete (red inputs pending) | B7: =COUNTIF('03 MASTER RATE LIBRARY'!W5:W400,">0") -> 34
A8: Unit = cft | B8: =COUNTIF('03 MASTER RATE LIBRARY'!G5:G400,"cft") -> 39
A9: Unit = Sft | B9: =COUNTIF('03 MASTER RATE LIBRARY'!G5:G400,"Sft") -> 60
A10: Unit = kg | B10: =COUNTIF('03 MASTER RATE LIBRARY'!G5:G400,"kg") -> 1
A11: Selected city | B11: =City -> Lahore
A12: Items fully priced for selected city | B12: =COUNTIF('03 MASTER RATE LIBRARY'!W5:W400,0) -> 126
A13: Red inputs listed in RFQ | B13: =COUNTA('16 VENDOR ENQUIRY (RFQ)'!B5:B500) -> 79
A14: RFQ lines quoted | B14: =COUNT('16 VENDOR ENQUIRY (RFQ)'!H5:H500) -> 0
A15: Sources registered | B15: =COUNTA('09 SOURCE REGISTER'!A5:A50) -> 46
A16: Rates by trade | B16: Count
A17: Concrete (CIV-CON) | B17: =COUNTIF('03 MASTER RATE LIBRARY'!A5:A400,"CIV-CON-*") -> 24
A18: Reinforcement (CIV-RFT) | B18: =COUNTIF('03 MASTER RATE LIBRARY'!A5:A400,"CIV-RFT-*") -> 2
A19: Formwork (CIV-FWK) | B19: =COUNTIF('03 MASTER RATE LIBRARY'!A5:A400,"CIV-FWK-*") -> 6
A20: Masonry (CIV-MAS) | B20: =COUNTIF('03 MASTER RATE LIBRARY'!A5:A400,"CIV-MAS-*") -> 11
A21: Plaster (FIN-PLS) | B21: =COUNTIF('03 MASTER RATE LIBRARY'!A5:A400,"FIN-PLS-*") -> 5
A22: Screed (FIN-SCR) | B22: =COUNTIF('03 MASTER RATE LIBRARY'!A5:A400,"FIN-SCR-*") -> 4
A23: Skirting (FIN-SKT) | B23: =COUNTIF('03 MASTER RATE LIBRARY'!A5:A400,"FIN-SKT-*") -> 1
A24: Waterproofing (FIN-WPF) | B24: =COUNTIF('03 MASTER RATE LIBRARY'!A5:A400,"FIN-WPF-*") -> 3
A25: Flooring (FIN-FLR) | B25: =COUNTIF('03 MASTER RATE LIBRARY'!A5:A400,"FIN-FLR-*") -> 9
A26: Wall finishes (FIN-WAL) | B26: =COUNTIF('03 MASTER RATE LIBRARY'!A5:A400,"FIN-WAL-*") -> 4
A27: Ceilings (FIN-CLG) | B27: =COUNTIF('03 MASTER RATE LIBRARY'!A5:A400,"FIN-CLG-*") -> 5
A28: Painting (FIN-PNT) | B28: =COUNTIF('03 MASTER RATE LIBRARY'!A5:A400,"FIN-PNT-*") -> 2
A29: Prelims (PRE) | B29: =COUNTIF('03 MASTER RATE LIBRARY'!A5:A400,"PRE-*") -> 7
A30: Earthwork (CIV-EW) | B30: =COUNTIF('03 MASTER RATE LIBRARY'!A5:A400,"CIV-EW-*") -> 7
A31: Doors (FIN-DOR) | B31: =COUNTIF('03 MASTER RATE LIBRARY'!A5:A400,"FIN-DOR-*") -> 3
A32: Windows (FIN-WIN) | B32: =COUNTIF('03 MASTER RATE LIBRARY'!A5:A400,"FIN-WIN-*") -> 2
A33: Joinery (FIN-JNR) | B33: =COUNTIF('03 MASTER RATE LIBRARY'!A5:A400,"FIN-JNR-*") -> 1
A34: Façade (FAC) | B34: =COUNTIF('03 MASTER RATE LIBRARY'!A5:A400,"FAC-*") -> 7
A35: External (EXT) | B35: =COUNTIF('03 MASTER RATE LIBRARY'!A5:A400,"EXT-*") -> 7
A36: Plumbing (PLB) | B36: =COUNTIF('03 MASTER RATE LIBRARY'!A5:A400,"PLB-*") -> 17
A37: Fire fighting (FF) | B37: =COUNTIF('03 MASTER RATE LIBRARY'!A5:A400,"FF-*") -> 6
A38: Electrical (ELE) | B38: =COUNTIF('03 MASTER RATE LIBRARY'!A5:A400,"ELE-*") -> 14
A39: ELV | B39: =COUNTIF('03 MASTER RATE LIBRARY'!A5:A400,"ELV-*") -> 2
A40: Life safety (LS) | B40: =COUNTIF('03 MASTER RATE LIBRARY'!A5:A400,"LS-*") -> 2
A41: HVAC | B41: =COUNTIF('03 MASTER RATE LIBRARY'!A5:A400,"MEP-HVAC-*") -> 4
...

Sheet 03 MASTER RATE LIBRARY
A1: 03 · MASTER RATE LIBRARY – selected city (links live to 04)
A2: Filter with header arrows. Rate Status turns INCOMPLETE while any red input in the analysis is blank.
A4: Item Code | B4: Trade | C4: Sub Trade | D4: Category | E4: Item Description | F4: Full Specification | G4: Unit | H4: Location | I4: Rate Date | J4: Material Cost | K4: Labour Cost | L4: Equipment Cost | M4: Transport Cost | N4: Wastage Cost | O4: Direct Cost | P4: Overheads | Q4: Profit | R4: Tax | S4: Final Rate PKR | T4: Rate per 100 units | U4: Rate Status | V4: Confidence | W4: Blank Inputs | X4: Source | Y4: Source Date | Z4: Source URL | AA4: Notes | AB4: Dup Code?
A5: CIV-CON-001 | B5: Civil | C5: Concrete | D5: 5000 PSI | E5: Providing and laying 5000 PSI concrete (Lab ACI 211.1 – 5000 PSI (W/C 0.34); mix per Image 1 – ACI 211.1 lab sheet) in structural members, including batching, placing, compacting and curing, complete in all respects; excluding reinforcement and formwork measured separately. | F5: Mix LAB-5000; cement 550 kg per lab batch; source Image 1 – ACI 211.1 lab sheet, dated 2026-04-05 | G5: cft | H5: =City -> Lahore | I5: 2026-09-27 | J5: ='04 DETAILED RATE ANALYSIS'!J17 -> 761.31063 | K5: ='04 DETAILED RATE ANALYSIS'!J20 -> 145.04 | L5: ='04 DETAILED RATE ANALYSIS'!J21 -> 65.59 | M5: ='04 DETAILED RATE ANALYSIS'!J22 -> 0 | N5: ='04 DETAILED RATE ANALYSIS'!J18 -> 21.957827 | O5: ='04 DETAILED RATE ANALYSIS'!J23 -> 993.89846 | P5: ='04 DETAILED RATE ANALYSIS'!J24+'04 DETAILED RATE ANALYSIS'!J25 -> 79.511877 | Q5: ='04 DETAILED RATE ANALYSIS'!J26 -> 99.389846 | R5: ='04 DETAILED RATE ANALYSIS'!J28 -> 0 | S5: ='04 DETAILED RATE ANALYSIS'!J29 -> 1173 | T5: =S5*100 -> 117300 | U5: =IF(W5>0,"INCOMPLETE – "&W5&" blank/old input(s)","Market-derived + assumptions") -> INCOMPLETE – 1 blank/old input(s) | V5: Low | W5: ='04 DETAILED RATE ANALYSIS'!J30 -> 1 | X5: See 09 SOURCE REGISTER (SRC-01…08) | Y5: 2026-04-25 to 2026-09-19 | Z5: see 09 | AA5: Admixture 7.69 kg = 1.2 L/100kg × 550 × SG 1.165 ✓. Required strength cell (20% extra) blank on sheet. | AB5: =IF(COUNTIF($A$5:$A$999,A5)>1,"DUPLICATE","")
A6: CIV-CON-002 | B6: Civil | C6: PCC / Lean concrete | D6: 1000 PSI | E6: Providing and laying 1000 PSI concrete (Lab – 1000 PSI (lean); mix per Image 2 – lab mix sheet) in sub-structure/PCC, including batching, placing, compacting and curing, complete in all respects; excluding reinforcement and formwork measured separately. | F6: Mix LAB-1000; cement 200 kg per lab batch; source Image 2 – lab mix sheet, dated Not visible | G6: cft | H6: =City -> Lahore | I6: 2026-09-27 | J6: ='04 DETAILED RATE ANALYSIS'!J44 -> 439.1663 | K6: ='04 DETAILED RATE ANALYSIS'!J47 -> 142.85 | L6: ='04 DETAILED RATE ANALYSIS'!J48 -> 74.9075 | M6: ='04 DETAILED RATE ANALYSIS'!J49 -> 0 | N6: ='04 DETAILED RATE ANALYSIS'!J45 -> 16.402517 | O6: ='04 DETAILED RATE ANALYSIS'!J50 -> 673.32632 | P6: ='04 DETAILED RATE ANALYSIS'!J51+'04 DETAILED RATE ANALYSIS'!J52 -> 53.866106 | Q6: ='04 DETAILED RATE ANALYSIS'!J53 -> 67.332632 | R6: ='04 DETAILED RATE ANALYSIS'!J55 -> 0 | S6: ='04 DETAILED RATE ANALYSIS'!J56 -> 795 | T6: =S6*100 -> 79500 | U6: =IF(W6>0,"INCOMPLETE – "&W6&" blank/old input(s)","Market-derived + assumptions") -> Market-derived + assumptions | V6: Low | W6: ='04 DETAILED RATE ANALYSIS'!J57 -> 0 | X6: See 09 SOURCE REGISTER (SRC-01…08) | Y6: 2026-04-25 to 2026-09-19 | Z6: see 09 | AA6: W/C 1.05 – very high; no admixture. Coarse source options Margalla/Sargodha/Sakhi Sarwar – Margalla (first listed) priced. | AB6: =IF(COUNTIF($A$5:$A$999,A6)>1,"DUPLICATE","")
A7: CIV-CON-003 | B7: Civil | C7: Concrete | D7: 6000 PSI | E7: Providing and laying 6000 PSI concrete (Lab – 6000 PSI (DHA Multan sheet); mix per Image 3 – lab mix sheet) in structural members, including batching, placing, compacting and curing, complete in all respects; excluding reinforcement and formwork measured separately. | F7: Mix LAB-6000; cement 550 kg per lab batch; source Image 3 – lab mix sheet, dated Not visible | G7: cft | H7: =City -> Lahore | I7: 2026-09-27 | J7: ='04 DETAILED RATE ANALYSIS'!J72 -> 735.20447 | K7: ='04 DETAILED RATE ANALYSIS'!J75 -> 145.04 | L7: ='04 DETAILED RATE ANALYSIS'!J76 -> 65.59 | M7: ='04 DETAILED RATE ANALYSIS'!J77 -> 0 | N7: ='04 DETAILED RATE ANALYSIS'!J73 -> 21.050989 | O7: ='04 DETAILED RATE ANALYSIS'!J78 -> 966.88546 | P7: ='04 DETAILED RATE ANALYSIS'!J79+'04 DETAILED RATE ANALYSIS'!J80 -> 77.350836 | Q7: ='04 DETAILED RATE ANALYSIS'!J81 -> 96.688546 | R7: ='04 DETAILED RATE ANALYSIS'!J83 -> 0 | S7: ='04 DETAILED RATE ANALYSIS'!J84 -> 1141 | T7: =S7*100 -> 114100 | U7: =IF(W7>0,"INCOMPLETE – "&W7&" blank/old input(s)","Market-derived + assumptions") -> INCOMPLETE – 1 blank/old input(s) | V7: Low | W7: ='04 DETAILED RATE ANALYSIS'!J85 -> 1 | X7: See 09 SOURCE REGISTER (SRC-01…08) | Y7: 2026-04-25 to 2026-09-19 | Z7: see 09 | AA7: Admixture entered in 'Admixture-2' row, Sika 512 row blank – product not identified. Slump 175 initial / 85 at 90 min. | AB7: =IF(COUNTIF($A$5:$A$999,A7)>1,"DUPLICATE","")
A8: CIV-CON-004 | B8: Civil | C8: PCC / Lean concrete | D8: 1:3:6 | E8: Providing and laying 1:3:6 concrete (Lab – 1:3:6 ratio (PCC); mix per Image 5 – lab mix sheet) in sub-structure/PCC, including batching, placing, compacting and curing, complete in all respects; excluding reinforcement and formwork measured separately. | F8: Mix LAB-136; cement 250 kg per lab batch; source Image 5 – lab mix sheet, dated Not visible | G8: cft | H8: =City -> Lahore | I8: 2026-09-27 | J8: ='04 DETAILED RATE ANALYSIS'!J99 -> 390.17416 | K8: ='04 DETAILED RATE ANALYSIS'!J102 -> 142.85 | L8: ='04 DETAILED RATE ANALYSIS'!J103 -> 74.9075 | M8: ='04 DETAILED RATE ANALYSIS'!J104 -> 0 | N8: ='04 DETAILED RATE ANALYSIS'!J100 -> 12.612038 | O8: ='04 DETAILED RATE ANALYSIS'!J105 -> 620.54369 | P8: ='04 DETAILED RATE ANALYSIS'!J106+'04 DETAILED RATE ANALYSIS'!J107 -> 49.643496 | Q8: ='04 DETAILED RATE ANALYSIS'!J108 -> 62.054369 | R8: ='04 DETAILED RATE ANALYSIS'!J110 -> 0 | S8: ='04 DETAILED RATE ANALYSIS'!J111 -> 732 | T8: =S8*100 -> 73200 | U8: =IF(W8>0,"INCOMPLETE – "&W8&" blank/old input(s)","Market-derived + assumptions") -> Market-derived + assumptions | V8: Low | W8: ='04 DETAILED RATE ANALYSIS'!J112 -> 0 | X8: See 09 SOURCE REGISTER (SRC-01…08) | Y8: 2026-04-25 to 2026-09-19 | Z8: see 09 | AA8: Labelled by ratio, not strength. Zinda Pir sand has no dated rate – item incomplete until entered. | AB8: =IF(COUNTIF($A$5:$A$999,A8)>1,"DUPLICATE","")
A9: CIV-CON-005 | B9: Civil | C9: Concrete | D9: 4500 PSI | E9: Providing and laying 4500 PSI concrete (Lab – 4500 PSI; mix per Image 6 – lab mix sheet) in structural members, including batching, placing, compacting and curing, complete in all respects; excluding reinforcement and formwork measured separately. | F9: Mix LAB-4500; cement 475 kg per lab batch; source Image 6 – lab mix sheet, dated Not visible | G9: cft | H9: =City -> Lahore | I9: 2026-09-27 | J9: ='04 DETAILED RATE ANALYSIS'!J127 -> 678.25042 | K9: ='04 DETAILED RATE ANALYSIS'!J130 -> 145.04 | L9: ='04 DETAILED RATE ANALYSIS'!J131 -> 65.59 | M9: ='04 DETAILED RATE ANALYSIS'!J132 -> 0 | N9: ='04 DETAILED RATE ANALYSIS'!J128 -> 20.261257 | O9: ='04 DETAILED RATE ANALYSIS'!J133 -> 909.14167 | P9: ='04 DETAILED RATE ANALYSIS'!J134+'04 DETAILED RATE ANALYSIS'!J135 -> 72.731334 | Q9: ='04 DETAILED RATE ANALYSIS'!J136 -> 90.914167 | R9: ='04 DETAILED RATE ANALYSIS'!J138 -> 0 | S9: ='04 DETAILED RATE ANALYSIS'!J139 -> 1073 | T9: =S9*100 -> 107300 | U9: =IF(W9>0,"INCOMPLETE – "&W9&" blank/old input(s)","Market-derived + assumptions") -> INCOMPLETE – 1 blank/old input(s) | V9: Low | W9: ='04 DETAILED RATE ANALYSIS'!J140 -> 1 | X9: See 09 SOURCE REGISTER (SRC-01…08) | Y9: 2026-04-25 to 2026-09-19 | Z9: see 09 | AA9: Slump 190 initial / 90 at 90 min. | AB9: =IF(COUNTIF($A$5:$A$999,A9)>1,"DUPLICATE","")
A10: CIV-CON-006 | B10: Civil | C10: Concrete | D10: 4000 PSI | E10: Providing and laying 4000 PSI concrete (Lab – 4000 PSI; mix per Image 8 – lab mix sheet) in structural members, including batching, placing, compacting and curing, complete in all respects; excluding reinforcement and formwork measured separately. | F10: Mix LAB-4000; cement 450 kg per lab batch; source Image 8 – lab mix sheet, dated Not visible | G10: cft | H10: =City -> Lahore | I10: 2026-09-27 | J10: ='04 DETAILED RATE ANALYSIS'!J155 -> 658.04544 | K10: ='04 DETAILED RATE ANALYSIS'!J158 -> 145.04 | L10: ='04 DETAILED RATE ANALYSIS'!J159 -> 65.59 | M10: ='04 DETAILED RATE ANALYSIS'!J160 -> 0 | N10: ='04 DETAILED RATE ANALYSIS'!J156 -> 19.984792 | O10: ='04 DETAILED RATE ANALYSIS'!J161 -> 888.66024 | P10: ='04 DETAILED RATE ANALYSIS'!J162+'04 DETAILED RATE ANALYSIS'!J163 -> 71.092819 | Q10: ='04 DETAILED RATE ANALYSIS'!J164 -> 88.866024 | R10: ='04 DETAILED RATE ANALYSIS'!J166 -> 0 | S10: ='04 DETAILED RATE ANALYSIS'!J167 -> 1049 | T10: =S10*100 -> 104900 | U10: =IF(W10>0,"INCOMPLETE – "&W10&" blank/old input(s)","Market-derived + assumptions") -> INCOMPLETE – 1 blank/old input(s) | V10: Low | W10: ='04 DETAILED RATE ANALYSIS'!J168 -> 1 | X10: See 09 SOURCE REGISTER (SRC-01…08) | Y10: 2026-04-25 to 2026-09-19 | Z10: see 09 | AA10: Slump 185 initial / 100 at 90 min. | AB10: =IF(COUNTIF($A$5:$A$999,A10)>1,"DUPLICATE","")
A11: CIV-CON-007 | B11: Civil | C11: PCC / Lean concrete | D11: 1500 PSI | E11: Providing and laying 1500 PSI concrete (ACI-211 batch sheet – 1500 PSI; mix per Image 4 – ACI-211 summary (QA/QC)) in sub-structure/PCC, including batching, placing, compacting and curing, complete in all respects; excluding reinforcement and formwork measured separately. | F11: Mix ACI-1500; cement 180 kg per lab batch; source Image 4 – ACI-211 summary (QA/QC), dated Not dated | G11: cft | H11: =City -> Lahore | I11: 2026-09-27 | J11: ='04 DETAILED RATE ANALYSIS'!J181 -> 432.69259 | K11: ='04 DETAILED RATE ANALYSIS'!J184 -> 142.85 | L11: ='04 DETAILED RATE ANALYSIS'!J185 -> 74.9075 | M11: ='04 DETAILED RATE ANALYSIS'!J186 -> 0 | N11: ='04 DETAILED RATE ANALYSIS'!J182 -> 16.643153 | O11: ='04 DETAILED RATE ANALYSIS'!J187 -> 667.09324 | P11: ='04 DETAILED RATE ANALYSIS'!J188+'04 DETAILED RATE ANALYSIS'!J189 -> 53.367459 | Q11: ='04 DETAILED RATE ANALYSIS'!J190 -> 66.709324 | R11: ='04 DETAILED RATE ANALYSIS'!J192 -> 0 | S11: ='04 DETAILED RATE ANALYSIS'!J193 -> 787 | T11: =S11*100 -> 78700 | U11: =IF(W11>0,"INCOMPLETE – "&W11&" blank/old input(s)","Market-derived + assumptions") -> Market-derived + assumptions | V11: Low | W11: ='04 DETAILED RATE ANALYSIS'!J194 -> 0 | X11: See 09 SOURCE REGISTER (SRC-01…08) | Y11: 2026-04-25 to 2026-09-19 | Z11: see 09 | AA11: Crush given as combined 1220 kg. Sheet unsigned/undated. | AB11: =IF(COUNTIF($A$5:$A$999,A11)>1,"DUPLICATE","")
A12: CIV-CON-008 | B12: Civil | C12: Concrete | D12: 4000 PSI | E12: Providing and laying 4000 PSI concrete (ACI-211 batch sheet – 4000 PSI; mix per Image 4 – ACI-211 summary) in structural members, including batching, placing, compacting and curing, complete in all respects; excluding reinforcement and formwork measured separately. | F12: Mix ACI-4000; cement 350 kg per lab batch; source Image 4 – ACI-211 summary, dated Not dated | G12: cft | H12: =City -> Lahore | I12: 2026-09-27 | J12: ='04 DETAILED RATE ANALYSIS'!J210 -> 589.95414 | K12: ='04 DETAILED RATE ANALYSIS'!J213 -> 145.04 | L12: ='04 DETAILED RATE ANALYSIS'!J214 -> 65.59 | M12: ='04 DETAILED RATE ANALYSIS'!J215 -> 0 | N12: ='04 DETAILED RATE ANALYSIS'!J211 -> 19.253675 | O12: ='04 DETAILED RATE ANALYSIS'!J216 -> 819.83782 | P12: ='04 DETAILED RATE ANALYSIS'!J217+'04 DETAILED RATE ANALYSIS'!J218 -> 65.587025 | Q12: ='04 DETAILED RATE ANALYSIS'!J219 -> 81.983782 | R12: ='04 DETAILED RATE ANALYSIS'!J221 -> 0 | S12: ='04 DETAILED RATE ANALYSIS'!J222 -> 967 | T12: =S12*100 -> 96700 | U12: =IF(W12>0,"INCOMPLETE – "&W12&" blank/old input(s)","Market-derived + assumptions") -> INCOMPLETE – 1 blank/old input(s) | V12: Low | W12: ='04 DETAILED RATE ANALYSIS'!J223 -> 1 | X12: See 09 SOURCE REGISTER (SRC-01…08) | Y12: 2026-04-25 to 2026-09-19 | Z12: see 09 | AA12: Cement 350 kg is 22% below lab 4000 (450) and 18% below J7 4000 (425) – verify trial-mix results. | AB12: =IF(COUNTIF($A$5:$A$999,A12)>1,"DUPLICATE","")
A13: CIV-CON-009 | B13: Civil | C13: Concrete | D13: 4500 PSI | E13: Providing and laying 4500 PSI concrete (ACI-211 batch sheet – 4500 PSI; mix per Image 4 – ACI-211 summary) in structural members, including batching, placing, compacting and curing, complete in all respects; excluding reinforcement and formwork measured separately. | F13: Mix ACI-4500; cement 400 kg per lab batch; source Image 4 – ACI-211 summary, dated Not dated | G13: cft | H13: =City -> Lahore | I13: 2026-09-27 | J13: ='04 DETAILED RATE ANALYSIS'!J239 -> 628.8755 | K13: ='04 DETAILED RATE ANALYSIS'!J242 -> 145.04 | L13: ='04 DETAILED RATE ANALYSIS'!J243 -> 65.59 | M13: ='04 DETAILED RATE ANALYSIS'!J244 -> 0 | N13: ='04 DETAILED RATE ANALYSIS'!J240 -> 19.822583 | O13: ='04 DETAILED RATE ANALYSIS'!J245 -> 859.32808 | P13: ='04 DETAILED RATE ANALYSIS'!J246+'04 DETAILED RATE ANALYSIS'!J247 -> 68.746246 | Q13: ='04 DETAILED RATE ANALYSIS'!J248 -> 85.932808 | R13: ='04 DETAILED RATE ANALYSIS'!J250 -> 0 | S13: ='04 DETAILED RATE ANALYSIS'!J251 -> 1014 | T13: =S13*100 -> 101400 | U13: =IF(W13>0,"INCOMPLETE – "&W13&" blank/old input(s)","Market-derived + assumptions") -> INCOMPLETE – 1 blank/old input(s) | V13: Low | W13: ='04 DETAILED RATE ANALYSIS'!J252 -> 1 | X13: See 09 SOURCE REGISTER (SRC-01…08) | Y13: 2026-04-25 to 2026-09-19 | Z13: see 09 | AB13: =IF(COUNTIF($A$5:$A$999,A13)>1,"DUPLICATE","")
A14: CIV-CON-010 | B14: Civil | C14: Concrete | D14: 6000 PSI | E14: Providing and laying 6000 PSI concrete (ACI-211 batch sheet – 6000 PSI; mix per Image 4 – ACI-211 summary) in structural members, including batching, placing, compacting and curing, complete in all respects; excluding reinforcement and formwork measured separately. | F14: Mix ACI-6000; cement 520 kg per lab batch; source Image 4 – ACI-211 summary, dated Not dated | G14: cft | H14: =City -> Lahore | I14: 2026-09-27 | J14: ='04 DETAILED RATE ANALYSIS'!J268 -> 727.64087 | K14: ='04 DETAILED RATE ANALYSIS'!J271 -> 145.04 | L14: ='04 DETAILED RATE ANALYSIS'!J272 -> 65.59 | M14: ='04 DETAILED RATE ANALYSIS'!J273 -> 0 | N14: ='04 DETAILED RATE ANALYSIS'!J269 -> 21.320019 | O14: ='04 DETAILED RATE ANALYSIS'!J274 -> 959.59089 | P14: ='04 DETAILED RATE ANALYSIS'!J275+'04 DETAILED RATE ANALYSIS'!J276 -> 76.767271 | Q14: ='04 DETAILED RATE ANALYSIS'!J277 -> 95.959089 | R14: ='04 DETAILED RATE ANALYSIS'!J279 -> 0 | S14: ='04 DETAILED RATE ANALYSIS'!J280 -> 1132 | T14: =S14*100 -> 113200 | U14: =IF(W14>0,"INCOMPLETE – "&W14&" blank/old input(s)","Market-derived + assumptions") -> INCOMPLETE – 1 blank/old input(s) | V14: Low | W14: ='04 DETAILED RATE ANALYSIS'!J281 -> 1 | X14: See 09 SOURCE REGISTER (SRC-01…08) | Y14: 2026-04-25 to 2026-09-19 | Z14: see 09 | AB14: =IF(COUNTIF($A$5:$A$999,A14)>1,"DUPLICATE","")
A15: CIV-CON-011 | B15: Civil | C15: Concrete | D15: 3000 PSI | E15: Providing and laying 3000 PSI concrete (J7 Emporium Mall B-17 batching plant – 3000 PSI; mix per Image 7 – J7 Group summary of batch weights) in structural members, including batching, placing, compacting and curing, complete in all respects; excluding reinforcement and formwork measured separately. | F15: Mix J7-3000; cement 325 kg per lab batch; source Image 7 – J7 Group summary of batch weights, dated 2024-03-08 (trials Jan-2024) | G15: cft | H15: =City -> Lahore | I15: 2026-09-27 | J15: ='04 DETAILED RATE ANALYSIS'!J297 -> 551.8277 | K15: ='04 DETAILED RATE ANALYSIS'!J300 -> 145.04 | L15: ='04 DETAILED RATE ANALYSIS'!J301 -> 65.59 | M15: ='04 DETAILED RATE ANALYSIS'!J302 -> 0 | N15: ='04 DETAILED RATE ANALYSIS'!J298 -> 18.197414 | O15: ='04 DETAILED RATE ANALYSIS'!J303 -> 780.65512 | P15: ='04 DETAILED RATE ANALYSIS'!J304+'04 DETAILED RATE ANALYSIS'!J305 -> 62.452409 | Q15: ='04 DETAILED RATE ANALYSIS'!J306 -> 78.065512 | R15: ='04 DETAILED RATE ANALYSIS'!J308 -> 0 | S15: ='04 DETAILED RATE ANALYSIS'!J309 -> 921 | T15: =S15*100 -> 92100 | U15: =IF(W15>0,"INCOMPLETE – "&W15&" blank/old input(s)","Market-derived + assumptions") -> INCOMPLETE – 1 blank/old input(s) | V15: Low | W15: ='04 DETAILED RATE ANALYSIS'!J310 -> 1 | X15: See 09 SOURCE REGISTER (SRC-01…08) | Y15: 2026-04-25 to 2026-09-19 | Z15: see 09 | AA15: Trial mix TM#16 17-01-2024. Sheet dated 2024 – older than other mixes. Crush 1/2" only 105 kg vs 3/8" 738 kg (fine-graded coarse). | AB15: =IF(COUNTIF($A$5:$A$999,A15)>1,"DUPLICATE","")
A16: CIV-CON-012 | B16: Civil | C16: Concrete | D16: 4000 PSI | E16: Providing and laying 4000 PSI concrete (J7 Emporium Mall B-17 batching plant – 4000 PSI; mix per Image 7 – J7 Group summary of batch weights) in structural members, including batching, placing, compacting and curing, complete in all respects; excluding reinforcement and formwork measured separately. | F16: Mix J7-4000; cement 425 kg per lab batch; source Image 7 – J7 Group summary of batch weights, dated 2024-03-08 (trials Jan-2024) | G16: cft | H16: =City -> Lahore | I16: 2026-09-27 | J16: ='04 DETAILED RATE ANALYSIS'!J326 -> 639.94701 | K16: ='04 DETAILED RATE ANALYSIS'!J329 -> 145.04 | L16: ='04 DETAILED RATE ANALYSIS'!J330 -> 65.59 | M16: ='04 DETAILED RATE ANALYSIS'!J331 -> 0 | N16: ='04 DETAILED RATE ANALYSIS'!J327 -> 19.556572 | O16: ='04 DETAILED RATE ANALYSIS'!J332 -> 870.13358 | P16: ='04 DETAILED RATE ANALYSIS'!J333+'04 DETAILED RATE ANALYSIS'!J334 -> 69.610687 | Q16: ='04 DETAILED RATE ANALYSIS'!J335 -> 87.013358 | R16: ='04 DETAILED RATE ANALYSIS'!J337 -> 0 | S16: ='04 DETAILED RATE ANALYSIS'!J338 -> 1027 | T16: =S16*100 -> 102700 | U16: =IF(W16>0,"INCOMPLETE – "&W16&" blank/old input(s)","Market-derived + assumptions") -> INCOMPLETE – 1 blank/old input(s) | V16: Low | W16: ='04 DETAILED RATE ANALYSIS'!J339 -> 1 | X16: See 09 SOURCE REGISTER (SRC-01…08) | Y16: 2026-04-25 to 2026-09-19 | Z16: see 09 | AA16: Trial mix TM#11 13-01-2024. Sheet dated 2024 – older than other mixes. Crush 1/2" only 105 kg vs 3/8" 738 kg (fine-graded coarse). | AB16: =IF(COUNTIF($A$5:$A$999,A16)>1,"DUPLICATE","")
A17: CIV-CON-013 | B17: Civil | C17: Concrete | D17: 4500 PSI | E17: Providing and laying 4500 PSI concrete (J7 Emporium Mall B-17 batching plant – 4500 PSI; mix per Image 7 – J7 Group summary of batch weights) in structural members, including batching, placing, compacting and curing, complete in all respects; excluding reinforcement and formwork measured separately. | F17: Mix J7-4500; cement 465 kg per lab batch; source Image 7 – J7 Group summary of batch weights, dated 2024-03-08 (trials Jan-2024) | G17: cft | H17: =City -> Lahore | I17: 2026-09-27 | J17: ='04 DETAILED RATE ANALYSIS'!J355 -> 676.90158 | K17: ='04 DETAILED RATE ANALYSIS'!J358 -> 145.04 | L17: ='04 DETAILED RATE ANALYSIS'!J359 -> 65.59 | M17: ='04 DETAILED RATE ANALYSIS'!J360 -> 0 | N17: ='04 DETAILED RATE ANALYSIS'!J356 -> 20.19832 | O17: ='04 DETAILED RATE ANALYSIS'!J361 -> 907.7299 | P17: ='04 DETAILED RATE ANALYSIS'!J362+'04 DETAILED RATE ANALYSIS'!J363 -> 72.618392 | Q17: ='04 DETAILED RATE ANALYSIS'!J364 -> 90.77299 | R17: ='04 DETAILED RATE ANALYSIS'!J366 -> 0 | S17: ='04 DETAILED RATE ANALYSIS'!J367 -> 1071 | T17: =S17*100 -> 107100 | U17: =IF(W17>0,"INCOMPLETE – "&W17&" blank/old input(s)","Market-derived + assumptions") -> INCOMPLETE – 1 blank/old input(s) | V17: Low | W17: ='04 DETAILED RATE ANALYSIS'!J368 -> 1 | X17: See 09 SOURCE REGISTER (SRC-01…08) | Y17: 2026-04-25 to 2026-09-19 | Z17: see 09 | AA17: Trial mix TM#15 17-01-2024. Sheet dated 2024 – older than other mixes. Crush 1/2" only 105 kg vs 3/8" 738 kg (fine-graded coarse). | AB17: =IF(COUNTIF($A$5:$A$999,A17)>1,"DUPLICATE","")
A18: CIV-CON-014 | B18: Civil | C18: Concrete | D18: 5000 PSI | E18: Providing and laying 5000 PSI concrete (J7 Emporium Mall B-17 batching plant – 5000 PSI; mix per Image 7 – J7 Group summary of batch weights) in structural members, including batching, placing, compacting and curing, complete in all respects; excluding reinforcement and formwork measured separately. | F18: Mix J7-5000; cement 515 kg per lab batch; source Image 7 – J7 Group summary of batch weights, dated 2024-03-08 (trials Jan-2024) | G18: cft | H18: =City -> Lahore | I18: 2026-09-27 | J18: ='04 DETAILED RATE ANALYSIS'!J384 -> 717.22618 | K18: ='04 DETAILED RATE ANALYSIS'!J387 -> 145.04 | L18: ='04 DETAILED RATE ANALYSIS'!J388 -> 65.59 | M18: ='04 DETAILED RATE ANALYSIS'!J389 -> 0 | N18: ='04 DETAILED RATE ANALYSIS'!J385 -> 20.749153 | O18: ='04 DETAILED RATE ANALYSIS'!J390 -> 948.60534 | P18: ='04 DETAILED RATE ANALYSIS'!J391+'04 DETAILED RATE ANALYSIS'!J392 -> 75.888427 | Q18: ='04 DETAILED RATE ANALYSIS'!J393 -> 94.860534 | R18: ='04 DETAILED RATE ANALYSIS'!J395 -> 0 | S18: ='04 DETAILED RATE ANALYSIS'!J396 -> 1119 | T18: =S18*100 -> 111900 | U18: =IF(W18>0,"INCOMPLETE – "&W18&" blank/old input(s)","Market-derived + assumptions") -> INCOMPLETE – 1 blank/old input(s) | V18: Low | W18: ='04 DETAILED RATE ANALYSIS'!J397 -> 1 | X18: See 09 SOURCE REGISTER (SRC-01…08) | Y18: 2026-04-25 to 2026-09-19 | Z18: see 09 | AA18: Trial mix TM#12 15-01-2024. Sheet dated 2024 – older than other mixes. Crush 1/2" only 105 kg vs 3/8" 738 kg (fine-graded coarse). Admixture check: 1.42%×515=7.31 vs 7.29 stated (minor). | AB18: =IF(COUNTIF($A$5:$A$999,A18)>1,"DUPLICATE","")
A19: CIV-CON-015 | B19: Civil | C19: Concrete | D19: 5500 PSI | E19: Providing and laying 5500 PSI concrete (J7 Emporium Mall B-17 batching plant – 5500 PSI; mix per Image 7 – J7 Group summary of batch weights) in structural members, including batching, placing, compacting and curing, complete in all respects; excluding reinforcement and formwork measured separately. | F19: Mix J7-5500; cement 530 kg per lab batch; source Image 7 – J7 Group summary of batch weights, dated 2024-03-08 (trials Jan-2024) | G19: cft | H19: =City -> Lahore | I19: 2026-09-27 | J19: ='04 DETAILED RATE ANALYSIS'!J413 -> 729.59156 | K19: ='04 DETAILED RATE ANALYSIS'!J416 -> 145.04 | L19: ='04 DETAILED RATE ANALYSIS'!J417 -> 65.59 | M19: ='04 DETAILED RATE ANALYSIS'!J418 -> 0 | N19: ='04 DETAILED RATE ANALYSIS'!J414 -> 20.933031 | O19: ='04 DETAILED RATE ANALYSIS'!J419 -> 961.15459 | P19: ='04 DETAILED RATE ANALYSIS'!J420+'04 DETAILED RATE ANALYSIS'!J421 -> 76.892367 | Q19: ='04 DETAILED RATE ANALYSIS'!J422 -> 96.115459 | R19: ='04 DETAILED RATE ANALYSIS'!J424 -> 0 | S19: ='04 DETAILED RATE ANALYSIS'!J425 -> 1134 | T19: =S19*100 -> 113400 | U19: =IF(W19>0,"INCOMPLETE – "&W19&" blank/old input(s)","Market-derived + assumptions") -> INCOMPLETE – 1 blank/old input(s) | V19: Low | W19: ='04 DETAILED RATE ANALYSIS'!J426 -> 1 | X19: See 09 SOURCE REGISTER (SRC-01…08) | Y19: 2026-04-25 to 2026-09-19 | Z19: see 09 | AA19: Trial mix TM#13 15-01-2024. Sheet dated 2024 – older than other mixes. Crush 1/2" only 105 kg vs 3/8" 738 kg (fine-graded coarse). | AB19: =IF(COUNTIF($A$5:$A$999,A19)>1,"DUPLICATE","")
A20: CIV-CON-016 | B20: Civil | C20: PCC / Lean concrete | D20: Nominal 1:4:8 | E20: Providing and laying plain cement concrete 1:4:8 (nominal volumetric, site-mixed) using OPC, Chenab sand and Margalla crush, including mixing, placing, compacting and curing, complete in all respects; excluding reinforcement and formwork measured separately. | F20: Nominal volumetric 1:4:8, dry factor 1.54, 1 bag = 1.25 cft (house standard); Lahore basis sand | G20: cft | H20: =City -> Lahore | I20: 2026-09-27 | J20: ='04 DETAILED RATE ANALYSIS'!J438 -> 359.37914 | K20: ='04 DETAILED RATE ANALYSIS'!J441 -> 142.85 | L20: ='04 DETAILED RATE ANALYSIS'!J442 -> 46.5875 | M20: ='04 DETAILED RATE ANALYSIS'!J443 -> 0 | N20: ='04 DETAILED RATE ANALYSIS'!J439 -> 13.409846 | O20: ='04 DETAILED RATE ANALYSIS'!J444 -> 562.22648 | P20: ='04 DETAILED RATE ANALYSIS'!J445+'04 DETAILED RATE ANALYSIS'!J446 -> 44.978119 | Q20: ='04 DETAILED RATE ANALYSIS'!J447 -> 56.222648 | R20: ='04 DETAILED RATE ANALYSIS'!J449 -> 0 | S20: ='04 DETAILED RATE ANALYSIS'!J450 -> 663 | T20: =S20*100 -> 66300 | U20: =IF(W20>0,"INCOMPLETE – "&W20&" blank/old input(s)","Market-derived + assumptions") -> Market-derived + assumptions | V20: Medium | W20: ='04 DETAILED RATE ANALYSIS'!J451 -> 0 | X20: See 09 SOURCE REGISTER (SRC-01…08) | Y20: 2026-04-25 to 2026-09-19 | Z20: see 09 | AA20: House nominal-mix consumption; site-batched. | AB20: =IF(COUNTIF($A$5:$A$999,A20)>1,"DUPLICATE","")
A21: CIV-CON-017 | B21: Civil | C21: Concrete | D21: Nominal 1:2:4 | E21: Providing and laying reinforced cement concrete 1:2:4 (nominal volumetric, site-mixed) using OPC, Chenab sand and Margalla crush, including mixing, placing, compacting and curing, complete in all respects; excluding reinforcement and formwork measured separately. | F21: Nominal volumetric 1:2:4, dry factor 1.54, 1 bag = 1.25 cft (house standard); Lahore basis sand | G21: cft | H21: =City -> Lahore | I21: 2026-09-27 | J21: ='04 DETAILED RATE ANALYSIS'!J463 -> 473.8184 | K21: ='04 DETAILED RATE ANALYSIS'!J466 -> 145.04 | L21: ='04 DETAILED RATE ANALYSIS'!J467 -> 37.27 | M21: ='04 DETAILED RATE ANALYSIS'!J468 -> 0 | N21: ='04 DETAILED RATE ANALYSIS'!J464 -> 15.224 | O21: ='04 DETAILED RATE ANALYSIS'!J469 -> 671.3524 | P21: ='04 DETAILED RATE ANALYSIS'!J470+'04 DETAILED RATE ANALYSIS'!J471 -> 53.708192 | Q21: ='04 DETAILED RATE ANALYSIS'!J472 -> 67.13524 | R21: ='04 DETAILED RATE ANALYSIS'!J474 -> 0 | S21: ='04 DETAILED RATE ANALYSIS'!J475 -> 792 | T21: =S21*100 -> 79200 | U21: =IF(W21>0,"INCOMPLETE – "&W21&" blank/old input(s)","Market-derived + assumptions") -> Market-derived + assumptions | V21: Medium | W21: ='04 DETAILED RATE ANALYSIS'!J476 -> 0 | X21: See 09 SOURCE REGISTER (SRC-01…08) | Y21: 2026-04-25 to 2026-09-19 | Z21: see 09 | AA21: House nominal-mix consumption; site-batched. | AB21: =IF(COUNTIF($A$5:$A$999,A21)>1,"DUPLICATE","")
A22: CIV-CON-018 | B22: Civil | C22: Concrete | D22: Nominal 1:1.5:3 | E22: Providing and laying reinforced cement concrete 1:1.5:3 (nominal volumetric, site-mixed) using OPC, Chenab sand and Margalla crush, including mixing, placing, compacting and curing, complete in all respects; excluding reinforcement and formwork measured separately. | F22: Nominal volumetric 1:1.5:3, dry factor 1.54, 1 bag = 1.25 cft (house standard); Lahore basis sand | G22: cft | H22: =City -> Lahore | I22: 2026-09-27 | J22: ='04 DETAILED RATE ANALYSIS'!J488 -> 541.4416 | K22: ='04 DETAILED RATE ANALYSIS'!J491 -> 145.04 | L22: ='04 DETAILED RATE ANALYSIS'!J492 -> 37.27 | M22: ='04 DETAILED RATE ANALYSIS'!J493 -> 0 | N22: ='04 DETAILED RATE ANALYSIS'!J489 -> 16.296 | O22: ='04 DETAILED RATE ANALYSIS'!J494 -> 740.0476 | P22: ='04 DETAILED RATE ANALYSIS'!J495+'04 DETAILED RATE ANALYSIS'!J496 -> 59.203808 | Q22: ='04 DETAILED RATE ANALYSIS'!J497 -> 74.00476 | R22: ='04 DETAILED RATE ANALYSIS'!J499 -> 0 | S22: ='04 DETAILED RATE ANALYSIS'!J500 -> 873 | T22: =S22*100 -> 87300 | U22: =IF(W22>0,"INCOMPLETE – "&W22&" blank/old input(s)","Market-derived + assumptions") -> Market-derived + assumptions | V22: Medium | W22: ='04 DETAILED RATE ANALYSIS'!J501 -> 0 | X22: See 09 SOURCE REGISTER (SRC-01…08) | Y22: 2026-04-25 to 2026-09-19 | Z22: see 09 | AA22: House nominal-mix consumption; site-batched. | AB22: =IF(COUNTIF($A$5:$A$999,A22)>1,"DUPLICATE","")
A23: CIV-RFT-001 | B23: Civil | C23: Reinforcement | D23: Gr.60 deformed | E23: Providing, cutting, bending and fixing Grade 60 deformed steel reinforcement including binding wire, chairs and spacers, complete in all respects. | F23: ASTM A615 Gr.60; laps measured in BBS; 3% cutting wastage | G23: kg | H23: =City -> Lahore | I23: 2026-09-27 | J23: ='04 DETAILED RATE ANALYSIS'!J509 -> 245.45 | K23: ='04 DETAILED RATE ANALYSIS'!J512 -> 11.077778 | L23: ='04 DETAILED RATE ANALYSIS'!J513 -> 0 | M23: ='04 DETAILED RATE ANALYSIS'!J514 -> 0 | N23: ='04 DETAILED RATE ANALYSIS'!J510 -> 7.26 | O23: ='04 DETAILED RATE ANALYSIS'!J515 -> 263.78778 | P23: ='04 DETAILED RATE ANALYSIS'!J516+'04 DETAILED RATE ANALYSIS'!J517 -> 21.103022 | Q23: ='04 DETAILED RATE ANALYSIS'!J518 -> 26.378778 | R23: ='04 DETAILED RATE ANALYSIS'!J520 -> 0 | S23: ='04 DETAILED RATE ANALYSIS'!J521 -> 311 | T23: =S23*100 -> 31100 | U23: =IF(W23>0,"INCOMPLETE – "&W23&" blank/old input(s)","Market-derived + assumptions") -> Market-derived + assumptions | V23: Medium | W23: ='04 DETAILED RATE ANALYSIS'!J522 -> 0 | X23: See 09 SOURCE REGISTER (SRC-01…08) | Y23: 2026-04-25 to 2026-09-19 | Z23: see 09 | AA23: Binding-wire rate blank. | AB23: =IF(COUNTIF($A$5:$A$999,A23)>1,"DUPLICATE","")
A24: CIV-MAS-001 | B24: Civil | C24: Masonry | D24: Brick 9" & above | E24: Providing and laying first class burnt brick masonry 9" thick and above in cement sand mortar 1:6 in superstructure, including scaffolding, curing, complete in all respects. | F24: Brick 9"×4.5"×3"; 13.5 bricks/cft; wet mortar 0.25 cft/cft × DryF_Mortar | G24: cft | H24: =City -> Lahore | I24: 2026-09-27 | J24: ='04 DETAILED RATE ANALYSIS'!J531 -> 317.03571 | K24: ='04 DETAILED RATE ANALYSIS'!J534 -> 90.14 | L24: ='04 DETAILED RATE ANALYSIS'!J535 -> 0 | M24: ='04 DETAILED RATE ANALYSIS'!J536 -> 0 | N24: ='04 DETAILED RATE ANALYSIS'!J532 -> 14.096786 | O24: ='04 DETAILED RATE ANALYSIS'!J537 -> 421.2725 | P24: ='04 DETAILED RATE ANALYSIS'!J538+'04 DETAILED RATE ANALYSIS'!J539 -> 33.7018 | Q24: ='04 DETAILED RATE ANALYSIS'!J540 -> 42.12725 | R24: ='04 DETAILED RATE ANALYSIS'!J542 -> 0 | S24: ='04 DETAILED RATE ANALYSIS'!J543 -> 497 | T24: =S24*100 -> 49700 | U24: =IF(W24>0,"INCOMPLETE – "&W24&" blank/old input(s)","Market-derived + assumptions") -> Market-derived + assumptions | V24: Medium | W24: ='04 DETAILED RATE ANALYSIS'!J544 -> 0 | X24: See 09 SOURCE REGISTER (SRC-01…08) | Y24: 2026-04-25 to 2026-09-19 | Z24: see 09 | AA24: Scaffolding for elevation work above GF to be added separately (house rule). | AB24: =IF(COUNTIF($A$5:$A$999,A24)>1,"DUPLICATE","")
A25: FIN-PLS-001 | B25: Finishes | C25: Plaster | D25: 0.5" cement plaster 1:4 | E25: Providing and applying 0.5" thick cement sand plaster 1:4 to walls, internal, including curing, complete in all respects. | F25: Thickness 0.0417 ft + 20% for undulations; dry factor 1.30 | G25: Sft | H25: =City -> Lahore | I25: 2026-09-27 | J25: ='04 DETAILED RATE ANALYSIS'!J552 -> 20.54 | K25: ='04 DETAILED RATE ANALYSIS'!J555 -> 36.88 | L25: ='04 DETAILED RATE ANALYSIS'!J556 -> 0 | M25: ='04 DETAILED RATE ANALYSIS'!J557 -> 0 | N25: ='04 DETAILED RATE ANALYSIS'!J553 -> 0.5356 | O25: ='04 DETAILED RATE ANALYSIS'!J558 -> 57.9556 | P25: ='04 DETAILED RATE ANALYSIS'!J559+'04 DETAILED RATE ANALYSIS'!J560 -> 4.636448 | Q25: ='04 DETAILED RATE ANALYSIS'!J561 -> 5.79556 | R25: ='04 DETAILED RATE ANALYSIS'!J563 -> 0 | S25: ='04 DETAILED RATE ANALYSIS'!J564 -> 68 | T25: =S25*100 -> 6800 | U25: =IF(W25>0,"INCOMPLETE – "&W25&" blank/old input(s)","Market-derived + assumptions") -> Market-derived + assumptions | V25: Medium | W25: ='04 DETAILED RATE ANALYSIS'!J565 -> 0 | X25: See 09 SOURCE REGISTER (SRC-01…08) | Y25: 2026-04-25 to 2026-09-19 | Z25: see 09 | AA25: Internal only – external elevation adds scaffold/cradle item. | AB25: =IF(COUNTIF($A$5:$A$999,A25)>1,"DUPLICATE","")
A26: FIN-PLS-002 | B26: Finishes | C26: Plaster | D26: 0.75" cement plaster 1:6 | E26: Providing and applying 0.75" thick cement sand plaster 1:6 to walls, internal, including curing, complete in all respects. | F26: Thickness 0.0625 ft + 20% for undulations; dry factor 1.30 | G26: Sft | H26: =City -> Lahore | I26: 2026-09-27 | J26: ='04 DETAILED RATE ANALYSIS'!J573 -> 24.235714 | K26: ='04 DETAILED RATE ANALYSIS'!J576 -> 46.1 | L26: ='04 DETAILED RATE ANALYSIS'!J577 -> 0 | M26: ='04 DETAILED RATE ANALYSIS'!J578 -> 0 | N26: ='04 DETAILED RATE ANALYSIS'!J574 -> 0.68528571 | O26: ='04 DETAILED RATE ANALYSIS'!J579 -> 71.021 | P26: ='04 DETAILED RATE ANALYSIS'!J580+'04 DETAILED RATE ANALYSIS'!J581 -> 5.68168 | Q26: ='04 DETAILED RATE ANALYSIS'!J582 -> 7.1021 | R26: ='04 DETAILED RATE ANALYSIS'!J584 -> 0 | S26: ='04 DETAILED RATE ANALYSIS'!J585 -> 84 | T26: =S26*100 -> 8400 | U26: =IF(W26>0,"INCOMPLETE – "&W26&" blank/old input(s)","Market-derived + assumptions") -> Market-derived + assumptions | V26: Medium | W26: ='04 DETAILED RATE ANALYSIS'!J586 -> 0 | X26: See 09 SOURCE REGISTER (SRC-01…08) | Y26: 2026-04-25 to 2026-09-19 | Z26: see 09 | AA26: Internal only – external elevation adds scaffold/cradle item. | AB26: =IF(COUNTIF($A$5:$A$999,A26)>1,"DUPLICATE","")
A27: CIV-FWK-001 | B27: Civil | C27: Formwork | D27: Slab soffit | E27: Providing, erecting and stripping plywood formwork to horizontal soffit of slabs incl. staging/props, including release oil, cleaning and repairs, complete in all respects; measured as contact area. | F27: 3/4" plywood, Reuse_Ply uses; timber Reuse_Tim uses; ground-floor base, no floor premium | G27: Sft | H27: =City -> Lahore | I27: 2026-09-27 | J27: ='04 DETAILED RATE ANALYSIS'!J597 -> 50.835833 | K27: ='04 DETAILED RATE ANALYSIS'!J600 -> 26.253333 | L27: ='04 DETAILED RATE ANALYSIS'!J601 -> 10 | M27: ='04 DETAILED RATE ANALYSIS'!J602 -> 0 | N27: ='04 DETAILED RATE ANALYSIS'!J598 -> 2.8645833 | O27: ='04 DETAILED RATE ANALYSIS'!J603 -> 89.95375 | P27: ='04 DETAILED RATE ANALYSIS'!J604+'04 DETAILED RATE ANALYSIS'!J605 -> 7.1963 | Q27: ='04 DETAILED RATE ANALYSIS'!J606 -> 8.995375 | R27: ='04 DETAILED RATE ANALYSIS'!J608 -> 0 | S27: ='04 DETAILED RATE ANALYSIS'!J609 -> 106 | T27: =S27*100 -> 10600 | U27: =IF(W27>0,"INCOMPLETE – "&W27&" blank/old input(s)","Market-derived + assumptions") -> Market-derived + assumptions | V27: Low | W27: ='04 DETAILED RATE ANALYSIS'!J610 -> 0 | X27: See 09 SOURCE REGISTER (SRC-01…08) | Y27: 2026-04-25 to 2026-09-19 | Z27: see 09 | AA27: Rate depends on repetitions (10 ASSUMPTIONS). Timber rate is OLD (Feb-2025). | AB27: =IF(COUNTIF($A$5:$A$999,A27)>1,"DUPLICATE","")
A28: CIV-FWK-002 | B28: Civil | C28: Formwork | D28: Beam sides & soffit | E28: Providing, erecting and stripping plywood formwork to beam sides and soffits incl. props, including release oil, cleaning and repairs, complete in all respects; measured as contact area. | F28: 3/4" plywood, Reuse_Ply uses; timber Reuse_Tim uses; ground-floor base, no floor premium | G28: Sft | H28: =City -> Lahore | I28: 2026-09-27 | J28: ='04 DETAILED RATE ANALYSIS'!J621 -> 54.515833 | K28: ='04 DETAILED RATE ANALYSIS'!J624 -> 39.38 | L28: ='04 DETAILED RATE ANALYSIS'!J625 -> 10 | M28: ='04 DETAILED RATE ANALYSIS'!J626 -> 0 | N28: ='04 DETAILED RATE ANALYSIS'!J622 -> 2.8645833 | O28: ='04 DETAILED RATE ANALYSIS'!J627 -> 106.76042 | P28: ='04 DETAILED RATE ANALYSIS'!J628+'04 DETAILED RATE ANALYSIS'!J629 -> 8.5408333 | Q28: ='04 DETAILED RATE ANALYSIS'!J630 -> 10.676042 | R28: ='04 DETAILED RATE ANALYSIS'!J632 -> 0 | S28: ='04 DETAILED RATE ANALYSIS'!J633 -> 126 | T28: =S28*100 -> 12600 | U28: =IF(W28>0,"INCOMPLETE – "&W28&" blank/old input(s)","Market-derived + assumptions") -> Market-derived + assumptions | V28: Low | W28: ='04 DETAILED RATE ANALYSIS'!J634 -> 0 | X28: See 09 SOURCE REGISTER (SRC-01…08) | Y28: 2026-04-25 to 2026-09-19 | Z28: see 09 | AA28: Rate depends on repetitions (10 ASSUMPTIONS). Timber rate is OLD (Feb-2025). | AB28: =IF(COUNTIF($A$5:$A$999,A28)>1,"DUPLICATE","")
A29: CIV-FWK-003 | B29: Civil | C29: Formwork | D29: Columns | E29: Providing, erecting and stripping plywood formwork to column faces incl. yokes, ties and bracing, including release oil, cleaning and repairs, complete in all respects; measured as contact area. | F29: 3/4" plywood, Reuse_Ply uses; timber Reuse_Tim uses; ground-floor base, no floor premium | G29: Sft | H29: =City -> Lahore | I29: 2026-09-27 | J29: ='04 DETAILED RATE ANALYSIS'!J644 -> 52.675833 | K29: ='04 DETAILED RATE ANALYSIS'!J647 -> 32.816667 | L29: ='04 DETAILED RATE ANALYSIS'!J648 -> 0 | M29: ='04 DETAILED RATE ANALYSIS'!J649 -> 0 | N29: ='04 DETAILED RATE ANALYSIS'!J645 -> 2.8645833 | O29: ='04 DETAILED RATE ANALYSIS'!J650 -> 88.357083 | P29: ='04 DETAILED RATE ANALYSIS'!J651+'04 DETAILED RATE ANALYSIS'!J652 -> 7.0685667 | Q29: ='04 DETAILED RATE ANALYSIS'!J653 -> 8.8357083 | R29: ='04 DETAILED RATE ANALYSIS'!J655 -> 0 | S29: ='04 DETAILED RATE ANALYSIS'!J656 -> 104 | T29: =S29*100 -> 10400 | U29: =IF(W29>0,"INCOMPLETE – "&W29&" blank/old input(s)","Market-derived + assumptions") -> Market-derived + assumptions | V29: Low | W29: ='04 DETAILED RATE ANALYSIS'!J657 -> 0 | X29: See 09 SOURCE REGISTER (SRC-01…08) | Y29: 2026-04-25 to 2026-09-19 | Z29: see 09 | AA29: Rate depends on repetitions (10 ASSUMPTIONS). Timber rate is OLD (Feb-2025). | AB29: =IF(COUNTIF($A$5:$A$999,A29)>1,"DUPLICATE","")
A30: CIV-FWK-004 | B30: Civil | C30: Formwork | D30: Walls / shear walls / lift core | E30: Providing, erecting and stripping plywood formwork to wall faces (each face measured) incl. ties and bracing, including release oil, cleaning and repairs, complete in all respects; measured as contact area. | F30: 3/4" plywood, Reuse_Ply uses; timber Reuse_Tim uses; ground-floor base, no floor premium | G30: Sft | H30: =City -> Lahore | I30: 2026-09-27 | J30: ='04 DETAILED RATE ANALYSIS'!J667 -> 54.515833 | K30: ='04 DETAILED RATE ANALYSIS'!J670 -> 30.292308 | L30: ='04 DETAILED RATE ANALYSIS'!J671 -> 0 | M30: ='04 DETAILED RATE ANALYSIS'!J672 -> 0 | N30: ='04 DETAILED RATE ANALYSIS'!J668 -> 2.8645833 | O30: ='04 DETAILED RATE ANALYSIS'!J673 -> 87.672724 | P30: ='04 DETAILED RATE ANALYSIS'!J674+'04 DETAILED RATE ANALYSIS'!J675 -> 7.0138179 | Q30: ='04 DETAILED RATE ANALYSIS'!J676 -> 8.7672724 | R30: ='04 DETAILED RATE ANALYSIS'!J678 -> 0 | S30: ='04 DETAILED RATE ANALYSIS'!J679 -> 103 | T30: =S30*100 -> 10300 | U30: =IF(W30>0,"INCOMPLETE – "&W30&" blank/old input(s)","Market-derived + assumptions") -> Market-derived + assumptions | V30: Low | W30: ='04 DETAILED RATE ANALYSIS'!J680 -> 0 | X30: See 09 SOURCE REGISTER (SRC-01…08) | Y30: 2026-04-25 to 2026-09-19 | Z30: see 09 | AA30: Rate depends on repetitions (10 ASSUMPTIONS). Timber rate is OLD (Feb-2025). | AB30: =IF(COUNTIF($A$5:$A$999,A30)>1,"DUPLICATE","")
A31: CIV-MAS-003 | B31: Civil | C31: Masonry | D31: 8" hollow block | E31: Providing and laying 8" hollow block masonry 8" thick in cement sand mortar 1:6 in walls and partitions, including curing, complete in all respects; openings >1.0 Sft deducted. | F31: Block 16"x8"x8"; 3/8" joints; hollow cores unfilled; lintels/bond beams measured separately | G31: Sft | H31: =City -> Lahore | I31: 2026-09-27 | J31: ='04 DETAILED RATE ANALYSIS'!J689 -> 234.86222 | K31: ='04 DETAILED RATE ANALYSIS'!J692 -> 37.38 | L31: ='04 DETAILED RATE ANALYSIS'!J693 -> 0 | M31: ='04 DETAILED RATE ANALYSIS'!J694 -> 0 | N31: ='04 DETAILED RATE ANALYSIS'!J690 -> 11.431182 | O31: ='04 DETAILED RATE ANALYSIS'!J695 -> 283.6734 | P31: ='04 DETAILED RATE ANALYSIS'!J696+'04 DETAILED RATE ANALYSIS'!J697 -> 22.693872 | Q31: ='04 DETAILED RATE ANALYSIS'!J698 -> 28.36734 | R31: ='04 DETAILED RATE ANALYSIS'!J700 -> 0 | S31: ='04 DETAILED RATE ANALYSIS'!J701 -> 335 | T31: =S31*100 -> 33500 | U31: =IF(W31>0,"INCOMPLETE – "&W31&" blank/old input(s)","Market-derived + assumptions") -> Market-derived + assumptions | V31: Medium | W31: ='04 DETAILED RATE ANALYSIS'!J702 -> 0 | X31: See 09 SOURCE REGISTER (SRC-01…08) | Y31: 2026-04-25 to 2026-09-19 | Z31: see 09 | AA31: Block rate ex-factory per SRC-09 – check freight. Scaffold for elevation work extra. | AB31: =IF(COUNTIF($A$5:$A$999,A31)>1,"DUPLICATE","")
A32: CIV-MAS-004 | B32: Civil | C32: Masonry | D32: 6" hollow block | E32: Providing and laying 6" hollow block masonry 6" thick in cement sand mortar 1:6 in walls and partitions, including curing, complete in all respects; openings >1.0 Sft deducted. | F32: Block 16"x6"x8"; 3/8" joints; hollow cores unfilled; lintels/bond beams measured separately | G32: Sft | H32: =City -> Lahore | I32: 2026-09-27 | J32: ='04 DETAILED RATE ANALYSIS'!J711 -> 184.02179 | K32: ='04 DETAILED RATE ANALYSIS'!J714 -> 31.15 | L32: ='04 DETAILED RATE ANALYSIS'!J715 -> 0 | M32: ='04 DETAILED RATE ANALYSIS'!J716 -> 0 | N32: ='04 DETAILED RATE ANALYSIS'!J712 -> 8.967143 | O32: ='04 DETAILED RATE ANALYSIS'!J717 -> 224.13894 | P32: ='04 DETAILED RATE ANALYSIS'!J718+'04 DETAILED RATE ANALYSIS'!J719 -> 17.931115 | Q32: ='04 DETAILED RATE ANALYSIS'!J720 -> 22.413894 | R32: ='04 DETAILED RATE ANALYSIS'!J722 -> 0 | S32: ='04 DETAILED RATE ANALYSIS'!J723 -> 264 | T32: =S32*100 -> 26400 | U32: =IF(W32>0,"INCOMPLETE – "&W32&" blank/old input(s)","Market-derived + assumptions") -> Market-derived + assumptions | V32: Medium | W32: ='04 DETAILED RATE ANALYSIS'!J724 -> 0 | X32: See 09 SOURCE REGISTER (SRC-01…08) | Y32: 2026-04-25 to 2026-09-19 | Z32: see 09 | AA32: Block rate ex-factory per SRC-09 – check freight. Scaffold for elevation work extra. | AB32: =IF(COUNTIF($A$5:$A$999,A32)>1,"DUPLICATE","")
A33: CIV-MAS-005 | B33: Civil | C33: Masonry | D33: 4" solid block | E33: Providing and laying 4" solid block masonry 4" thick in cement sand mortar 1:6 in walls and partitions, including curing, complete in all respects; openings >1.0 Sft deducted. | F33: Block 12"x4"x8"; 3/8" joints; hollow cores unfilled; lintels/bond beams measured separately | G33: Sft | H33: =City -> Lahore | I33: 2026-09-27 | J33: ='04 DETAILED RATE ANALYSIS'!J733 -> 202.45926 | K33: ='04 DETAILED RATE ANALYSIS'!J736 -> 24.92 | L33: ='04 DETAILED RATE ANALYSIS'!J737 -> 0 | M33: ='04 DETAILED RATE ANALYSIS'!J738 -> 0 | N33: ='04 DETAILED RATE ANALYSIS'!J734 -> 9.9504529 | O33: ='04 DETAILED RATE ANALYSIS'!J739 -> 237.32972 | P33: ='04 DETAILED RATE ANALYSIS'!J740+'04 DETAILED RATE ANALYSIS'!J741 -> 18.986377 | Q33: ='04 DETAILED RATE ANALYSIS'!J742 -> 23.732972 | R33: ='04 DETAILED RATE ANALYSIS'!J744 -> 0 | S33: ='04 DETAILED RATE ANALYSIS'!J745 -> 280 | T33: =S33*100 -> 28000 | U33: =IF(W33>0,"INCOMPLETE – "&W33&" blank/old input(s)","Market-derived + assumptions") -> Market-derived + assumptions | V33: Medium | W33: ='04 DETAILED RATE ANALYSIS'!J746 -> 0 | X33: See 09 SOURCE REGISTER (SRC-01…08) | Y33: 2026-04-25 to 2026-09-19 | Z33: see 09 | AA33: Block rate ex-factory per SRC-09 – check freight. Scaffold for elevation work extra. | AB33: =IF(COUNTIF($A$5:$A$999,A33)>1,"DUPLICATE","")
A34: CIV-MAS-002 | B34: Civil | C34: Masonry | D34: Brick 4.5" | E34: Providing and laying first class burnt brick masonry 4.5" thick in cement sand mortar 1:4 in partitions, including curing, complete in all respects. | F34: 0.375 ft thick; 13.5 bricks/cft; wet mortar 0.25 cft/cft | G34: Sft | H34: =City -> Lahore | I34: 2026-09-27 | J34: ='04 DETAILED RATE ANALYSIS'!J755 -> 127.10625 | K34: ='04 DETAILED RATE ANALYSIS'!J758 -> 31.15 | L34: ='04 DETAILED RATE ANALYSIS'!J759 -> 0 | M34: ='04 DETAILED RATE ANALYSIS'!J760 -> 0 | N34: ='04 DETAILED RATE ANALYSIS'!J756 -> 5.4339375 | O34: ='04 DETAILED RATE ANALYSIS'!J761 -> 163.69019 | P34: ='04 DETAILED RATE ANALYSIS'!J762+'04 DETAILED RATE ANALYSIS'!J763 -> 13.095215 | Q34: ='04 DETAILED RATE ANALYSIS'!J764 -> 16.369019 | R34: ='04 DETAILED RATE ANALYSIS'!J766 -> 0 | S34: ='04 DETAILED RATE ANALYSIS'!J767 -> 193 | T34: =S34*100 -> 19300 | U34: =IF(W34>0,"INCOMPLETE – "&W34&" blank/old input(s)","Market-derived + assumptions") -> Market-derived + assumptions | V34: Medium | W34: ='04 DETAILED RATE ANALYSIS'!J768 -> 0 | X34: See 09 SOURCE REGISTER (SRC-01…08) | Y34: 2026-04-25 to 2026-09-19 | Z34: see 09 | AB34: =IF(COUNTIF($A$5:$A$999,A34)>1,"DUPLICATE","")
A35: FIN-SCR-001 | B35: Finishes | C35: Screed | D35: 1.5" screed 1:4 | E35: Providing and laying 1.5" thick cement sand screed 1:4 to floors/roofs, laid to level or falls, including bonding slurry and curing, complete in all respects. | F35: Thickness 0.1250 ft + 5% for level tolerance; dry factor 1.30 | G35: Sft | H35: =City -> Lahore | I35: 2026-09-27 | J35: ='04 DETAILED RATE ANALYSIS'!J776 -> 53.9175 | K35: ='04 DETAILED RATE ANALYSIS'!J779 -> 55.536842 | L35: ='04 DETAILED RATE ANALYSIS'!J780 -> 0 | M35: ='04 DETAILED RATE ANALYSIS'!J781 -> 0 | N35: ='04 DETAILED RATE ANALYSIS'!J777 -> 1.40595 | O35: ='04 DETAILED RATE ANALYSIS'!J782 -> 110.86029 | P35: ='04 DETAILED RATE ANALYSIS'!J783+'04 DETAILED RATE ANALYSIS'!J784 -> 8.8688234 | Q35: ='04 DETAILED RATE ANALYSIS'!J785 -> 11.086029 | R35: ='04 DETAILED RATE ANALYSIS'!J787 -> 0 | S35: ='04 DETAILED RATE ANALYSIS'!J788 -> 131 | T35: =S35*100 -> 13100 | U35: =IF(W35>0,"INCOMPLETE – "&W35&" blank/old input(s)","Market-derived + assumptions") -> Market-derived + assumptions | V35: Medium | W35: ='04 DETAILED RATE ANALYSIS'!J789 -> 0 | X35: See 09 SOURCE REGISTER (SRC-01…08) | Y35: 2026-04-25 to 2026-09-19 | Z35: see 09 | AA35: Bonding slurry cement included in 5% tolerance. Screed >2" on roofs usually priced as concrete. | AB35: =IF(COUNTIF($A$5:$A$999,A35)>1,"DUPLICATE","")
A36: FIN-SCR-002 | B36: Finishes | C36: Screed | D36: 2.0" screed 1:4 | E36: Providing and laying 2.0" thick cement sand screed 1:4 to floors/roofs, laid to level or falls, including bonding slurry and curing, complete in all respects. | F36: Thickness 0.1667 ft + 5% for level tolerance; dry factor 1.30 | G36: Sft | H36: =City -> Lahore | I36: 2026-09-27 | J36: ='04 DETAILED RATE ANALYSIS'!J797 -> 71.89 | K36: ='04 DETAILED RATE ANALYSIS'!J800 -> 65.95 | L36: ='04 DETAILED RATE ANALYSIS'!J801 -> 0 | M36: ='04 DETAILED RATE ANALYSIS'!J802 -> 0 | N36: ='04 DETAILED RATE ANALYSIS'!J798 -> 1.8746 | O36: ='04 DETAILED RATE ANALYSIS'!J803 -> 139.7146 | P36: ='04 DETAILED RATE ANALYSIS'!J804+'04 DETAILED RATE ANALYSIS'!J805 -> 11.177168 | Q36: ='04 DETAILED RATE ANALYSIS'!J806 -> 13.97146 | R36: ='04 DETAILED RATE ANALYSIS'!J808 -> 0 | S36: ='04 DETAILED RATE ANALYSIS'!J809 -> 165 | T36: =S36*100 -> 16500 | U36: =IF(W36>0,"INCOMPLETE – "&W36&" blank/old input(s)","Market-derived + assumptions") -> Market-derived + assumptions | V36: Medium | W36: ='04 DETAILED RATE ANALYSIS'!J810 -> 0 | X36: See 09 SOURCE REGISTER (SRC-01…08) | Y36: 2026-04-25 to 2026-09-19 | Z36: see 09 | AA36: Bonding slurry cement included in 5% tolerance. Screed >2" on roofs usually priced as concrete. | AB36: =IF(COUNTIF($A$5:$A$999,A36)>1,"DUPLICATE","")
A37: FIN-SCR-003 | B37: Finishes | C37: Screed | D37: 3.0" screed 1:3 | E37: Providing and laying 3.0" thick cement sand screed 1:3 to floors/roofs, laid to level or falls, including bonding slurry and curing, complete in all respects. | F37: Thickness 0.2500 ft + 5% for level tolerance; dry factor 1.30 | G37: Sft | H37: =City -> Lahore | I37: 2026-09-27 | J37: ='04 DETAILED RATE ANALYSIS'!J818 -> 127.96875 | K37: ='04 DETAILED RATE ANALYSIS'!J821 -> 81.169231 | L37: ='04 DETAILED RATE ANALYSIS'!J822 -> 0 | M37: ='04 DETAILED RATE ANALYSIS'!J823 -> 0 | N37: ='04 DETAILED RATE ANALYSIS'!J819 -> 3.173625 | O37: ='04 DETAILED RATE ANALYSIS'!J824 -> 212.31161 | P37: ='04 DETAILED RATE ANALYSIS'!J825+'04 DETAILED RATE ANALYSIS'!J826 -> 16.984928 | Q37: ='04 DETAILED RATE ANALYSIS'!J827 -> 21.231161 | R37: ='04 DETAILED RATE ANALYSIS'!J829 -> 0 | S37: ='04 DETAILED RATE ANALYSIS'!J830 -> 251 | T37: =S37*100 -> 25100 | U37: =IF(W37>0,"INCOMPLETE – "&W37&" blank/old input(s)","Market-derived + assumptions") -> Market-derived + assumptions | V37: Medium | W37: ='04 DETAILED RATE ANALYSIS'!J831 -> 0 | X37: See 09 SOURCE REGISTER (SRC-01…08) | Y37: 2026-04-25 to 2026-09-19 | Z37: see 09 | AA37: Bonding slurry cement included in 5% tolerance. Screed >2" on roofs usually priced as concrete. | AB37: =IF(COUNTIF($A$5:$A$999,A37)>1,"DUPLICATE","")
A38: FIN-WPF-001 | B38: Finishes | C38: Waterproofing | D38: Torch-on APP membrane | E38: Providing and applying one layer 4-thick APP modified bitumen membrane, torch-applied over bitumen primer on roof/terrace slabs incl. upstands, laps and angle fillets, complete in all respects. | F38: Primer 0.023 litre/Sft; membrane with W_Mem laps; protection screed measured separately | G38: Sft | H38: =City -> Lahore | I38: 2026-09-27 | J38: ='04 DETAILED RATE ANALYSIS'!J841 -> 100.5865 | K38: ='04 DETAILED RATE ANALYSIS'!J844 -> 20.766667 | L38: ='04 DETAILED RATE ANALYSIS'!J845 -> 4.4444444 | M38: ='04 DETAILED RATE ANALYSIS'!J846 -> 0 | N38: ='04 DETAILED RATE ANALYSIS'!J842 -> 11.76 | O38: ='04 DETAILED RATE ANALYSIS'!J847 -> 137.55761 | P38: ='04 DETAILED RATE ANALYSIS'!J848+'04 DETAILED RATE ANALYSIS'!J849 -> 11.004609 | Q38: ='04 DETAILED RATE ANALYSIS'!J850 -> 13.755761 | R38: ='04 DETAILED RATE ANALYSIS'!J852 -> 0 | S38: ='04 DETAILED RATE ANALYSIS'!J853 -> 162 | T38: =S38*100 -> 16200 | U38: =IF(W38>0,"INCOMPLETE – "&W38&" blank/old input(s)","Market-derived + assumptions") -> INCOMPLETE – 1 blank/old input(s) | V38: Low | W38: ='04 DETAILED RATE ANALYSIS'!J854 -> 1 | X38: See 09 SOURCE REGISTER (SRC-01…08) | Y38: 2026-04-25 to 2026-09-19 | Z38: see 09 | AA38: Membrane often client-supplied – set MAT-MEM-APP consumption to 0 in that case. | AB38: =IF(COUNTIF($A$5:$A$999,A38)>1,"DUPLICATE","")
A39: FIN-WPF-002 | B39: Finishes | C39: Waterproofing | D39: Cementitious 2 coats | E39: Providing and applying two-coat polymer-modified cementitious waterproofing to toilets, wet areas and tanks, including surface preparation and corner reinforcement, complete in all respects. | F39: Total consumption 0.19 kg/Sft (2 coats) – confirm with product data sheet | G39: Sft | H39: =City -> Lahore | I39: 2026-09-27 | J39: ='04 DETAILED RATE ANALYSIS'!J861 -> 47 | K39: ='04 DETAILED RATE ANALYSIS'!J864 -> 12.46 | L39: ='04 DETAILED RATE ANALYSIS'!J865 -> 0 | M39: ='04 DETAILED RATE ANALYSIS'!J866 -> 0 | N39: ='04 DETAILED RATE ANALYSIS'!J862 -> 2.35 | O39: ='04 DETAILED RATE ANALYSIS'!J867 -> 61.81 | P39: ='04 DETAILED RATE ANALYSIS'!J868+'04 DETAILED RATE ANALYSIS'!J869 -> 4.9448 | Q39: ='04 DETAILED RATE ANALYSIS'!J870 -> 6.181 | R39: ='04 DETAILED RATE ANALYSIS'!J872 -> 0 | S39: ='04 DETAILED RATE ANALYSIS'!J873 -> 73 | T39: =S39*100 -> 7300 | U39: =IF(W39>0,"INCOMPLETE – "&W39&" blank/old input(s)","Market-derived + assumptions") -> INCOMPLETE – 1 blank/old input(s) | V39: Low | W39: ='04 DETAILED RATE ANALYSIS'!J874 -> 1 | X39: See 09 SOURCE REGISTER (SRC-01…08) | Y39: 2026-04-25 to 2026-09-19 | Z39: see 09 | AB39: =IF(COUNTIF($A$5:$A$999,A39)>1,"DUPLICATE","")
A40: FIN-WPF-003 | B40: Finishes | C40: Waterproofing | D40: DPC 1.5" + bitumen | E40: Providing and laying 1.5" thick damp proof course in cement concrete 1:2:4 with two coats of hot bitumen at plinth level, complete in all respects. | F40: 0.125 cft concrete per Sft; hot bitumen 0.10 kg/Sft (2 coats) | G40: Sft | H40: =City -> Lahore | I40: 2026-09-27 | J40: ='04 DETAILED RATE ANALYSIS'!J884 -> 78.6 | K40: ='04 DETAILED RATE ANALYSIS'!J887 -> 42.208 | L40: ='04 DETAILED RATE ANALYSIS'!J888 -> 0 | M40: ='04 DETAILED RATE ANALYSIS'!J889 -> 0 | N40: ='04 DETAILED RATE ANALYSIS'!J885 -> 1.903 | O40: ='04 DETAILED RATE ANALYSIS'!J890 -> 122.711 | P40: ='04 DETAILED RATE ANALYSIS'!J891+'04 DETAILED RATE ANALYSIS'!J892 -> 9.81688 | Q40: ='04 DETAILED RATE ANALYSIS'!J893 -> 12.2711 | R40: ='04 DETAILED RATE ANALYSIS'!J895 -> 0 | S40: ='04 DETAILED RATE ANALYSIS'!J896 -> 145 | T40: =S40*100 -> 14500 | U40: =IF(W40>0,"INCOMPLETE – "&W40&" blank/old input(s)","Market-derived + assumptions") -> Market-derived + assumptions | V40: Low | W40: ='04 DETAILED RATE ANALYSIS'!J897 -> 0 | X40: See 09 SOURCE REGISTER (SRC-01…08) | Y40: 2026-04-25 to 2026-09-19 | Z40: see 09 | AB40: =IF(COUNTIF($A$5:$A$999,A40)>1,"DUPLICATE","")
A41: FIN-FLR-001 | B41: Finishes | C41: Flooring | D41: Porcelain 24"x24" | E41: Providing and laying 24"x24" porcelain floor tiles of approved make on cementitious tile adhesive over prepared screed, including grouting, cleaning and protection, complete in all respects. | F41: Tile per selected product (PC); adhesive 1/60; 1/8" joints | G41: Sft | H41: =City -> Lahore | I41: 2026-09-27 | J41: ='04 DETAILED RATE ANALYSIS'!J906 -> 225.83333 | K41: ='04 DETAILED RATE ANALYSIS'!J909 -> 33.65 | L41: ='04 DETAILED RATE ANALYSIS'!J910 -> 0 | M41: ='04 DETAILED RATE ANALYSIS'!J911 -> 0 | N41: ='04 DETAILED RATE ANALYSIS'!J907 -> 15.171667 | O41: ='04 DETAILED RATE ANALYSIS'!J912 -> 274.655 | P41: ='04 DETAILED RATE ANALYSIS'!J913+'04 DETAILED RATE ANALYSIS'!J914 -> 21.9724 | Q41: ='04 DETAILED RATE ANALYSIS'!J915 -> 27.4655 | R41: ='04 DETAILED RATE ANALYSIS'!J917 -> 0 | S41: ='04 DETAILED RATE ANALYSIS'!J918 -> 324 | T41: =S41*100 -> 32400 | U41: =IF(W41>0,"INCOMPLETE – "&W41&" blank/old input(s)","Market-derived + assumptions") -> Market-derived + assumptions | V41: Medium | W41: ='04 DETAILED RATE ANALYSIS'!J919 -> 0 | X41: See 09 SOURCE REGISTER (SRC-01…08) | Y41: 2026-04-25 to 2026-09-19 | Z41: see 09 | AA41: Tile rate is a PC rate – set to selected series. Screed measured separately. | AB41: =IF(COUNTIF($A$5:$A$999,A41)>1,"DUPLICATE","")
...

Sheet 04 DETAILED RATE ANALYSIS
A1: 04 · DETAILED RATE ANALYSIS
A2: Amount = Adjusted Qty × Base Rate; Adjusted Qty = Consumption × (1 + Wastage). Base rates are live lookups from 05/06/07.
